<?xml version="1.0"?>
<robot 
    xmlns:xacro="http://www.ros.org/wiki/xacro" name="arm7dof">
    <xacro:property name="DH_d1" value="0.35" />
    <xacro:property name="DH_d2" value="0.25" />
    <xacro:property name="DH_d3" value="1" />
    <xacro:property name="DH_d4" value="-0.2" />
    <xacro:property name="DH_d5" value="1" />
    <xacro:property name="DH_d6" value="0.0" />
    <xacro:property name="DH_d7" value="0.2" />
    <xacro:property name="r_link" value="0.1" />
    <xacro:property name="r_base" value="0.3" />
    <xacro:property name="r_endplate" value="0.5" />
    <xacro:property name="L1" value="${DH_d1-r_link}" />
    <xacro:property name="L2" value="${2*(DH_d2-r_link)}" />
    <xacro:property name="L3" value="${DH_d3-r_link}" />
    <xacro:property name="L4" value="${2*(-DH_d4-r_link)}" />    
    <xacro:property name="L5" value="${DH_d5-r_link}" />
    <xacro:property name="L6" value="${2*(r_link)}" />
    <xacro:property name="L7" value="${(DH_d7-r_link)}" />
    <!--distance from wrist point to final flange frame is L7; want to fit 3 disks in this range -->
    <xacro:property name="L_flange_disk" value="${L7/3}" />
    
    
  <link name="world"/>

  <joint name="fixed" type="fixed">
    <parent link="world"/>
    <child link="link1"/>
  </joint>

  <link name="link1">
    <visual>
      <origin xyz="0 0 ${L1/2}" rpy="0 0 0" />
      <geometry>
          <cylinder length="${L1}" radius="${r_base}"/>
      </geometry>
    </visual>
    <collision>
      <geometry>
        <cylinder length="${L1}" radius="${r_base}"/>
      </geometry>
      <origin rpy="0 0 0" xyz="0 0 ${L1/2}"/>
    </collision>
	<inertial>
	  <mass value="30.0"/>
	  <origin rpy="0 0 0" xyz="0 0 0"/>
	  <inertia ixx="5" iyy="5" izz="20" ixy="0.0" ixz="0.0" iyz="0.0"/>
	</inertial>
  </link>

  <joint name="joint0" type="revolute">
    <parent link="link1"/>
    <child link="link2"/>
    <origin xyz="0 0 ${DH_d1}" rpy="0 0 0" />
    <axis xyz="0 0 1" />
    <dynamics damping="10"/>
    <limit lower="-3" upper="3" effort="1300" velocity="0.2"/>
  </joint>

  <link name="link2">
    <visual>
      <origin xyz="0 0 0" rpy="1.57 0 0" />
      <geometry>
          <cylinder length="${L2}" radius="${r_link}"/>
      </geometry>
    </visual>
    <collision>
      <origin xyz="0 0 0" rpy="1.57 0 0" />
      <geometry>
          <cylinder length="${L2}" radius="${0.95*r_link}"/>
      </geometry>
    </collision>
	<inertial>
	  <mass value="20"/>
	  <origin rpy="1.57 0 0" xyz="0 0 0"/>
	  <inertia ixx="0.3" iyy="0.1" izz="10" ixy="0" ixz="0" iyz="0"/>	  
	</inertial>
  </link>

  <joint name="joint1" type="revolute">
    <parent link="link2"/>
    <child link="link3"/>
    <origin xyz="0 ${DH_d2} 0" rpy="1.57 0 0" />
    <axis xyz="0 0 1" />
    <dynamics damping="10"/>
    <limit lower="-3" upper="3" effort="1300" velocity="0.2"/>
  </joint>

  <link name="link3">
    <visual>
      <origin xyz="0 ${L3/2} 0.0" rpy="-1.57 0 0" />
      <geometry>
          <cylinder length="${L3}" radius="${r_link}"/>
      </geometry>
    </visual>
    <collision>
      <origin xyz="0 ${L3/2} 0.0" rpy="-1.57 0 0" />
      <geometry>
          <cylinder length="${L3}" radius="${r_link}"/>   
      </geometry>
    </collision>
	<inertial>
	  <mass value="15"/>
	  <origin rpy="-1.57 0 0" xyz="0 0 0"/>
	  <inertia ixx="0.2" iyy="0.1" izz="10" ixy="0" ixz="0" iyz="0"/>
	</inertial>
  </link>

  <joint name="joint2" type="revolute">
    <parent link="link3"/>
    <child link="link4"/>
    <origin xyz="0 ${DH_d3} 0" rpy="-1.57 0 0" />
    <axis xyz="0 0 1" />
    <dynamics damping="5"/>
    <limit lower="-3.1" upper="2.8" effort="500" velocity="0.3"/>
  </joint>

  <link name="link4">
    <visual>
      <origin xyz="0 0 0" rpy="1.57 0 0" />
      <geometry>
          <cylinder length="${L4}" radius="${r_link}"/>
      </geometry>
    </visual>
    <collision>
      <origin xyz="0 0 0" rpy="1.57 0 0" />  
      <geometry>
         <cylinder length="${L4}" radius="${0.95*r_link}"/>
      </geometry>
    </collision>
	<inertial>
	  <mass value="15"/>
	  <origin rpy="-1.57 0 0" xyz="0 0 0"/>
	  <inertia ixx="2" iyy="0.1" izz="10" ixy="0" ixz="0" iyz="0"/>
	</inertial>
  </link>

  <joint name="joint3" type="revolute">
    <parent link="link4"/>
    <child link="link5"/>
    <origin xyz="0 ${DH_d4} 0" rpy="1.57 0 0" />
    <axis xyz="0 0 1" />
    <dynamics damping="1000"/>
    <limit lower="-3.1" upper="2.7" effort="500" velocity="0.3"/>
  </joint>

  <link name="link5">
     <visual>
      <origin xyz="0 ${L5/2} 0.0" rpy="-1.57 0 0" />
      <geometry>
          <cylinder length="${L5}" radius="${r_link}"/>
      </geometry>
    </visual>    
    <collision>
      <origin xyz="0 ${L5/2} 0.0" rpy="-1.57 0 0" />
      <geometry>
        <cylinder length="${L5}" radius="${r_link}"/>
      </geometry>
    </collision>
	<inertial>
	  <mass value="8"/>
	  <origin rpy="-1.57 0 0" xyz="0 0 0"/>
          <!-- iyy is rotation axis of link5 w/rt joint5-->
	  <inertia ixx="0.1" iyy="2" izz="3" ixy="0" ixz="0" iyz="0"/>
	</inertial>
  </link>

  <joint name="joint4" type="revolute">
    <parent link="link5"/>
    <child link="link6"/>
    <origin xyz="0 ${DH_d5} 0" rpy="-1.57 0 0" />
    <axis xyz="0 0 1" />
    <dynamics damping="30"/>
    <limit lower="-4." upper="1.5" effort="100" velocity="0.400"/>
  </joint>

  <link name="link6">
    <visual>
      <origin xyz="0 0.0 0" rpy="-1.57 0 0" />
      <geometry>
          <cylinder length="${L6}" radius="${r_link}"/>
      </geometry>
    </visual>    
    <collision>
      <origin xyz="0 0.0 0" rpy="-1.57 0 0" />
      <geometry>
          <cylinder length="${L6}" radius="${0.95*r_link}"/>
      </geometry>
    </collision>
	<inertial>
	  <mass value="6"/>
	  <origin rpy="1.57 0 0" xyz="0 0 0"/>
          <!-- proximal joint induces rotation about iyy of link6, so increase this inertia to account for reflected motor inertia-->
	  <inertia ixx="1" iyy="1" izz="1" ixy="0" ixz="0" iyz="0"/>	  
	</inertial>
  </link>

  <joint name="joint5" type="revolute">
    <parent link="link6"/>
    <child link="link7"/>
    <origin xyz="0 0 0" rpy="1.57 0 0" />
    <axis xyz="0 0 1" />
    <dynamics damping="30"/>
    <limit lower="-3" upper="3" effort="100" velocity="0.5"/>
  </joint>

  <link name="link7">
     <visual>
      <origin xyz="0 ${DH_d7-2.5*L_flange_disk} 0" rpy="-1.57 0 0" />
      <geometry>
          <cylinder length="${L_flange_disk}" radius="${r_link}"/>
      </geometry>
    </visual>
    <!--collision>
      <origin xyz="0 ${DH_d7-2.5*L_flange_disk} 0" rpy="-1.57 0 0" />
      <geometry>
          <cylinder length="${L_flange_disk}" radius="${r_link}"/>
      </geometry>
    </collision-->
	<inertial>
	  <mass value="4"/>
	  <origin rpy="-1.57 0 0" xyz="0 0 0"/>
	  <inertia ixx="0.03" iyy="1" izz="1" ixy="0" ixz="0" iyz="0"/>
	</inertial>
  </link>

  <joint name="joint6" type="revolute">
    <parent link="link7"/>
    <child link="link8"/>
    <origin xyz="0 ${DH_d7} 0" rpy="-1.57 0 0" />
    <axis xyz="0 0 1" />
    <dynamics damping="15"/>
    <limit lower="-4.5" upper="1.2" effort="70" velocity="0.4"/>
  </joint>

  <link name="link8">
    <visual>
      <origin xyz="0 0 ${-1.5*L_flange_disk}" rpy="0 0 0" />
      <geometry>
          <cylinder length="${L_flange_disk}" radius="${0.8*r_link}"/>
      </geometry>
    </visual>
    <!-- skip the collision model for this inner disk-->
    <!--collision>
      <origin xyz="0 0 ${-1.5*L_flange_disk}" rpy="0 0 0" />
      <geometry>
          <cylinder length="${L_flange_disk}" radius="${0.8*r_link}"/>
    </collision-->
	<inertial>
	  <mass value="4"/>
	  <origin rpy="0 0 0" xyz="0 0 0"/>
	  <!-- add more z inertia to help stabilize-->
	  <inertia ixx="0.03" iyy="0.03" izz="1" ixy="0" ixz="0" iyz="0"/>
	</inertial>
  </link>

  <transmission name="tran0">
	<type>transmission_interface/SimpleTransmission</type>
	<joint name="joint0">
	  <!--hardwareInterface>PositionJointInterface</hardwareInterface-->
	  <!--hardwareInterface>VelocityJointInterface</hardwareInterface-->
	  <hardwareInterface>EffortJointInterface</hardwareInterface>
	</joint>
	<actuator name="motor0">
	  <!--hardwareInterface>PositionJointInterface</hardwareInterface-->
	  <!--hardwareInterface>VelocityJointInterface</hardwareInterface-->
	  <hardwareInterface>EffortJointInterface</hardwareInterface>
	  <mechanicalReduction>7680</mechanicalReduction>
	</actuator>
  </transmission>

  <transmission name="tran1">
	<type>transmission_interface/SimpleTransmission</type>
	<joint name="joint1">
	  <!--hardwareInterface>PositionJointInterface</hardwareInterface-->
	  <!--hardwareInterface>VelocityJointInterface</hardwareInterface-->
	  <hardwareInterface>EffortJointInterface</hardwareInterface>
	</joint>
	<actuator name="motor1">
	  <!--hardwareInterface>PositionJointInterface</hardwareInterface-->
	  <!--hardwareInterface>VelocityJointInterface</hardwareInterface-->
	  <hardwareInterface>EffortJointInterface</hardwareInterface>
	  <mechanicalReduction>7680</mechanicalReduction>
	</actuator>
  </transmission>

  <transmission name="tran2">
	<type>transmission_interface/SimpleTransmission</type>
	<joint name="joint2">
	  <!--hardwareInterface>PositionJointInterface</hardwareInterface-->
	  <!--hardwareInterface>VelocityJointInterface</hardwareInterface-->
	  <hardwareInterface>EffortJointInterface</hardwareInterface>
	</joint>
	<actuator name="motor2">
	  <!--hardwareInterface>PositionJointInterface</hardwareInterface-->
	  <!--hardwareInterface>VelocityJointInterface</hardwareInterface-->
	  <hardwareInterface>EffortJointInterface</hardwareInterface>
	  <mechanicalReduction>3584</mechanicalReduction>
	</actuator>
  </transmission>

  <transmission name="tran3">
	<type>transmission_interface/SimpleTransmission</type>
	<joint name="joint3">
	  <!--hardwareInterface>PositionJointInterface</hardwareInterface-->
	  <!--hardwareInterface>VelocityJointInterface</hardwareInterface-->
	  <hardwareInterface>EffortJointInterface</hardwareInterface>
	</joint>
	<actuator name="motor3">
	  <!--hardwareInterface>PositionJointInterface</hardwareInterface-->
	  <!--hardwareInterface>VelocityJointInterface</hardwareInterface-->
	  <hardwareInterface>EffortJointInterface</hardwareInterface>
	  <mechanicalReduction>3584</mechanicalReduction>
	</actuator>
  </transmission>

  <transmission name="tran4">
	<type>transmission_interface/SimpleTransmission</type>
	<joint name="joint4">
	  <!--hardwareInterface>PositionJointInterface</hardwareInterface-->
	  <!--hardwareInterface>VelocityJointInterface</hardwareInterface-->
	  <hardwareInterface>EffortJointInterface</hardwareInterface>
	</joint>
	<actuator name="motor4">
	  <!--hardwareInterface>PositionJointInterface</hardwareInterface-->
	  <!--hardwareInterface>VelocityJointInterface</hardwareInterface-->
	  <hardwareInterface>EffortJointInterface</hardwareInterface>
	  <mechanicalReduction>3125</mechanicalReduction>
	</actuator>
  </transmission>

  <transmission name="tran5">
	<type>transmission_interface/SimpleTransmission</type>
	<joint name="joint5">
	  <!--hardwareInterface>PositionJointInterface</hardwareInterface-->
	  <!--hardwareInterface>VelocityJointInterface</hardwareInterface-->
	  <hardwareInterface>EffortJointInterface</hardwareInterface>
	</joint>
	<actuator name="motor5">
	  <!--hardwareInterface>PositionJointInterface</hardwareInterface-->
	  <!--hardwareInterface>VelocityJointInterface</hardwareInterface-->
	  <hardwareInterface>EffortJointInterface</hardwareInterface>
	  <mechanicalReduction>3125</mechanicalReduction>
	</actuator>
  </transmission>

  <transmission name="tran6">
	<type>transmission_interface/SimpleTransmission</type>
	<joint name="joint6">
	  <!--hardwareInterface>PositionJointInterface</hardwareInterface-->
	  <!--hardwareInterface>VelocityJointInterface</hardwareInterface-->
	  <hardwareInterface>EffortJointInterface</hardwareInterface>
	</joint>
	<actuator name="motor6">
	  <!--hardwareInterface>PositionJointInterface</hardwareInterface-->
	  <!--hardwareInterface>VelocityJointInterface</hardwareInterface-->
	  <hardwareInterface>EffortJointInterface</hardwareInterface>
	  <mechanicalReduction>3125</mechanicalReduction>
	</actuator>
  </transmission>
  
  <!--this is silly, but need to include transmission spec in order to get ft_sensor link frame published-->
  <transmission name="tran7">
	<type>transmission_interface/SimpleTransmission</type>
	<joint name="ft_sensor_jnt">
	  <!--hardwareInterface>PositionJointInterface</hardwareInterface-->
	  <!--hardwareInterface>VelocityJointInterface</hardwareInterface-->
	  <hardwareInterface>EffortJointInterface</hardwareInterface>
	</joint>
	<actuator name="motor7">
	  <!--hardwareInterface>PositionJointInterface</hardwareInterface-->
	  <!--hardwareInterface>VelocityJointInterface</hardwareInterface-->
	  <hardwareInterface>EffortJointInterface</hardwareInterface>
	  <mechanicalReduction>1</mechanicalReduction>
	</actuator>
  </transmission>  

    
    <gazebo>
     <plugin name="gazebo_ros_control" filename="libgazebo_ros_control.so">
       <robotNamespace>/arm7dof</robotNamespace>
     </plugin>
  </gazebo>
  
  
  <!--model a f/t sensor; set up a link and a joint -->
  <link name="ft_sensor_link">
      <collision>
          <origin xyz="0 0 ${-L_flange_disk/2}" rpy="0 0 0"/>
          <geometry>
            <cylinder length="${L_flange_disk}" radius="${r_endplate}"/> 
          </geometry>
      </collision>

      <visual>
          <origin xyz="0 0 ${-L_flange_disk/2}" rpy="0 0 0" />
          <geometry>
              <cylinder length="${L_flange_disk}" radius="${r_endplate}"/>
          </geometry>
          <material name="ft_sensor_color">
              <color rgba="1 0 0 1.0"/>
          </material>
      </visual>

      <inertial>
          <mass value="0.01" />
          <origin xyz="0 0 0" rpy="0 0 0"/>
          <inertia ixx="0.01" ixy="0" ixz="0" iyy="0.01" iyz="0" izz="0.01" />
      </inertial>
  </link>
  
  <!--ideally, this would be a static joint; until fixed in gazebo, must have dynamic jnt-->
  <joint name="ft_sensor_jnt" type="prismatic">
    <parent link="link8"/>
    <child link="ft_sensor_link"/>
    <origin xyz="0 0 -0.003" rpy="0 0 0"/>
    <axis xyz="0 0 1"/>
    <limit effort="100.0" lower="0" upper="0.0" velocity="0.01"/>
    <dynamics damping="1.0"/>    
  </joint>


    <!-- Enable Joint Feedback -->
    <gazebo reference="ft_sensor_jnt">
        <provideFeedback>true</provideFeedback>
    </gazebo>
    <!-- The ft_sensor plugin -->
    <gazebo>
        <plugin name="ft_sensor" filename="libgazebo_ros_ft_sensor.so">
            <updateRate>1000.0</updateRate>
            <topicName>ft_sensor_topic</topicName>
            <jointName>ft_sensor_jnt</jointName>
        </plugin>
    </gazebo>
</robot>
