<?xml version="1.0"?>
<robot  
    xmlns:xacro="http://www.ros.org/wiki/xacro" name="one_DOF_robot">

<!-- Used for fixing robot to Gazebo 'base_link' -->
  <link name="world"/>

  <joint name="glue_robot_to_world" type="fixed">
    <parent link="world"/>
    <child link="link1"/>
  </joint>

 <!-- Base Link -->
  <link name="link1">
    <collision>
      <origin xyz="0 0 0.5" rpy="0 0 0"/>
      <geometry>
       <box size="0.2 0.2 0.7"/>
      </geometry>
    </collision>

    <visual>
      <origin xyz="0 0 0.5" rpy="0 0 0"/>
      <geometry>
        <box size="0.2 0.2 1"/>
      </geometry>
    </visual>

    <inertial>
      <origin xyz="0 0 0.5" rpy="0 0 0"/>
      <mass value="1"/>
      <inertia
        ixx="1.0" ixy="0.0" ixz="0.0"
        iyy="1.0" iyz="0.0"
        izz="1.0"/>
    </inertial>
  </link>

<!-- Moveable Link -->
  <link name="link2">
    <collision>
      <origin xyz="0 0 0.5" rpy="0 0 0"/>
      <geometry>
        <cylinder length="1" radius="0.1"/>
        <!--box size="0.15 0.15 0.8"-->
      </geometry>
    </collision>

    <visual>
      <origin xyz="0 0 0.5" rpy="0 0 0"/>
      <geometry>
        <cylinder length="1" radius="0.1"/>
      </geometry>
    </visual>

    <inertial>
      <origin xyz="0 0 0.5" rpy="0 0 0"/>
      <mass value="1"/>
      <inertia
        ixx="0.1" ixy="0.0" ixz="0.0"
        iyy="0.1" iyz="0.0"
        izz="0.005"/>
    </inertial>
  </link>

  <joint name="joint1" type="prismatic">
    <parent link="link1"/>
    <child link="link2"/>
    <origin xyz="0 0 1" rpy="0 0 0"/>
    <axis xyz="0 0 1"/>
    <limit effort="100.0" lower="-2.0" upper="2.0" velocity="20.0"/>
    <dynamics damping="1.0"/>
  </joint>

  <transmission name="tran1">
    <type>transmission_interface/SimpleTransmission</type>
    <joint name="joint1">
      <hardwareInterface>EffortJointInterface</hardwareInterface>
    </joint>
    <actuator name="motor1">
      <hardwareInterface>EffortJointInterface</hardwareInterface>
      <mechanicalReduction>1</mechanicalReduction>
    </actuator>
  </transmission>
  <gazebo>
     <plugin name="gazebo_ros_control" filename="libgazebo_ros_control.so">
       <robotNamespace>/one_DOF_robot</robotNamespace>
     </plugin>
  </gazebo>


<!--model a f/t sensor; set up a link and a joint -->
  <link name="ft_sensor_link">
      <collision>
          <origin xyz="0 0 0" rpy="0 0 0"/>
          <geometry>
            <cylinder length="0.005" radius="0.05"/>
          </geometry>
      </collision>

      <visual>
          <origin xyz="0 0 0" rpy="0 0 0" />
          <geometry>
              <cylinder length="0.005" radius="0.05"/>
          </geometry>
          <material name="ft_sensor_color">
              <color rgba="1 0 0 1.0"/>
          </material>
      </visual>

      <inertial>
          <mass value="0.01" />
          <origin xyz="0 0 0" rpy="0 0 0"/>
          <inertia ixx="0.01" ixy="0" ixz="0" iyy="0.01" iyz="0" izz="0.01" />
      </inertial>
  </link>
  
  <!--ideally, this would be a static joint; until fixed in gazebo, must have dynamic jnt-->
  <joint name="ft_sensor_jnt" type="prismatic">
    <parent link="link2"/>
    <child link="ft_sensor_link"/>
    <origin xyz="0 0 1" rpy="0 0 0"/>
    <axis xyz="0 0 1"/>
    <limit effort="100.0" lower="0" upper="0.0" velocity="0.01"/>
    <dynamics damping="1.0"/>    
  </joint>


<!-- Enable the Joint Feedback -->
<gazebo reference="ft_sensor_jnt">
<provideFeedback>true</provideFeedback>
</gazebo>
<!-- The ft_sensor plugin -->
<gazebo>
<plugin name="ft_sensor" filename="libgazebo_ros_ft_sensor.so">
<updateRate>1000.0</updateRate>
<topicName>ft_sensor_topic</topicName>
<jointName>ft_sensor_jnt</jointName>
</plugin>
</gazebo>
  
</robot>

